2020-02-07 19:08:00,814 ERROR: Exception on /user/lexa [GET] [in C:\Users\a_smi\PycharmProjects\microblog\venv\lib\site-packages\flask\app.py:1891]
Traceback (most recent call last):
  File "C:\Users\a_smi\PycharmProjects\microblog\venv\lib\site-packages\flask\app.py", line 2446, in wsgi_app
    response = self.full_dispatch_request()
  File "C:\Users\a_smi\PycharmProjects\microblog\venv\lib\site-packages\flask\app.py", line 1951, in full_dispatch_request
    rv = self.handle_user_exception(e)
  File "C:\Users\a_smi\PycharmProjects\microblog\venv\lib\site-packages\flask\app.py", line 1820, in handle_user_exception
    reraise(exc_type, exc_value, tb)
  File "C:\Users\a_smi\PycharmProjects\microblog\venv\lib\site-packages\flask\_compat.py", line 39, in reraise
    raise value
  File "C:\Users\a_smi\PycharmProjects\microblog\venv\lib\site-packages\flask\app.py", line 1949, in full_dispatch_request
    rv = self.dispatch_request()
  File "C:\Users\a_smi\PycharmProjects\microblog\venv\lib\site-packages\flask\app.py", line 1935, in dispatch_request
    return self.view_functions[rule.endpoint](**req.view_args)
  File "C:\Users\a_smi\PycharmProjects\microblog\venv\lib\site-packages\flask_login\utils.py", line 261, in decorated_view
    return func(*args, **kwargs)
  File "C:\Users\a_smi\PycharmProjects\microblog\app\main\routes.py", line 77, in user
    next_url=next_url, prev_url=prev_url)
  File "C:\Users\a_smi\PycharmProjects\microblog\venv\lib\site-packages\flask\templating.py", line 140, in render_template
    ctx.app,
  File "C:\Users\a_smi\PycharmProjects\microblog\venv\lib\site-packages\flask\templating.py", line 120, in _render
    rv = template.render(context)
  File "C:\Users\a_smi\PycharmProjects\microblog\venv\lib\site-packages\jinja2\environment.py", line 1090, in render
    self.environment.handle_exception()
  File "C:\Users\a_smi\PycharmProjects\microblog\venv\lib\site-packages\jinja2\environment.py", line 832, in handle_exception
    reraise(*rewrite_traceback_stack(source=source))
  File "C:\Users\a_smi\PycharmProjects\microblog\venv\lib\site-packages\jinja2\_compat.py", line 28, in reraise
    raise value.with_traceback(tb)
  File "C:\Users\a_smi\PycharmProjects\microblog\app\templates\user.html", line 1, in top-level template code
    {% extends "base.html" %}
  File "C:\Users\a_smi\PycharmProjects\microblog\app\templates\base.html", line 1, in top-level template code
    {% extends 'bootstrap/base.html' %}
  File "C:\Users\a_smi\PycharmProjects\microblog\venv\lib\site-packages\flask_bootstrap\templates\bootstrap\base.html", line 1, in top-level template code
    {% block doc -%}
  File "C:\Users\a_smi\PycharmProjects\microblog\venv\lib\site-packages\flask_bootstrap\templates\bootstrap\base.html", line 3, in block "doc"
    <html{% block html_attribs %}{% endblock html_attribs %}>
  File "C:\Users\a_smi\PycharmProjects\microblog\venv\lib\site-packages\flask_bootstrap\templates\bootstrap\base.html", line 11, in block "html"
    {%- endblock metas %}
  File "C:\Users\a_smi\PycharmProjects\microblog\venv\lib\site-packages\flask_bootstrap\templates\bootstrap\base.html", line 12, in block "body"
  File "C:\Users\a_smi\PycharmProjects\microblog\app\templates\base.html", line 26, in block "navbar"
    action="{{ url_for('main.search') }}">
  File "C:\Users\a_smi\PycharmProjects\microblog\venv\lib\site-packages\flask\helpers.py", line 370, in url_for
    return appctx.app.handle_url_build_error(error, endpoint, values)
  File "C:\Users\a_smi\PycharmProjects\microblog\venv\lib\site-packages\flask\app.py", line 2215, in handle_url_build_error
    reraise(exc_type, exc_value, tb)
  File "C:\Users\a_smi\PycharmProjects\microblog\venv\lib\site-packages\flask\_compat.py", line 39, in reraise
    raise value
  File "C:\Users\a_smi\PycharmProjects\microblog\venv\lib\site-packages\flask\helpers.py", line 358, in url_for
    endpoint, values, method=method, force_external=external
  File "C:\Users\a_smi\PycharmProjects\microblog\venv\lib\site-packages\werkzeug\routing.py", line 2020, in build
    raise BuildError(endpoint, values, method, self)
werkzeug.routing.BuildError: Could not build url for endpoint 'main.search'. Did you mean 'main.user' instead?
2020-02-07 19:17:45,641 INFO: Microblog startup [in C:\Users\a_smi\PycharmProjects\microblog\app\__init__.py:77]
2020-02-07 19:17:57,886 ERROR: Exception on /search [GET] [in C:\Users\a_smi\PycharmProjects\microblog\venv\lib\site-packages\flask\app.py:1891]
Traceback (most recent call last):
  File "C:\Users\a_smi\PycharmProjects\microblog\venv\lib\site-packages\flask\app.py", line 2446, in wsgi_app
    response = self.full_dispatch_request()
  File "C:\Users\a_smi\PycharmProjects\microblog\venv\lib\site-packages\flask\app.py", line 1951, in full_dispatch_request
    rv = self.handle_user_exception(e)
  File "C:\Users\a_smi\PycharmProjects\microblog\venv\lib\site-packages\flask\app.py", line 1820, in handle_user_exception
    reraise(exc_type, exc_value, tb)
  File "C:\Users\a_smi\PycharmProjects\microblog\venv\lib\site-packages\flask\_compat.py", line 39, in reraise
    raise value
  File "C:\Users\a_smi\PycharmProjects\microblog\venv\lib\site-packages\flask\app.py", line 1949, in full_dispatch_request
    rv = self.dispatch_request()
  File "C:\Users\a_smi\PycharmProjects\microblog\venv\lib\site-packages\flask\app.py", line 1935, in dispatch_request
    return self.view_functions[rule.endpoint](**req.view_args)
  File "C:\Users\a_smi\PycharmProjects\microblog\venv\lib\site-packages\flask_login\utils.py", line 261, in decorated_view
    return func(*args, **kwargs)
  File "C:\Users\a_smi\PycharmProjects\microblog\app\main\routes.py", line 143, in search
    current_app.config['POSTS_PER_PAGE'])
  File "C:\Users\a_smi\PycharmProjects\microblog\app\models.py", line 82, in search
    ids, total = query_index(cls.__tablename__, expression, page, per_page)
  File "C:\Users\a_smi\PycharmProjects\microblog\app\search.py", line 25, in query_index
    'from': (page - 1) * per_page, 'size': per_page})
  File "C:\Users\a_smi\PycharmProjects\microblog\venv\lib\site-packages\elasticsearch\client\utils.py", line 84, in _wrapped
    return func(*args, params=params, **kwargs)
  File "C:\Users\a_smi\PycharmProjects\microblog\venv\lib\site-packages\elasticsearch\client\__init__.py", line 1548, in search
    "GET", _make_path(index, doc_type, "_search"), params=params, body=body
  File "C:\Users\a_smi\PycharmProjects\microblog\venv\lib\site-packages\elasticsearch\transport.py", line 358, in perform_request
    timeout=timeout,
  File "C:\Users\a_smi\PycharmProjects\microblog\venv\lib\site-packages\elasticsearch\connection\http_urllib3.py", line 261, in perform_request
    self._raise_error(response.status, raw_data)
  File "C:\Users\a_smi\PycharmProjects\microblog\venv\lib\site-packages\elasticsearch\connection\base.py", line 182, in _raise_error
    status_code, error_message, additional_info
elasticsearch.exceptions.NotFoundError: NotFoundError(404, 'index_not_found_exception', 'no such index [post]', post, index_or_alias)
2020-02-07 19:21:25,573 ERROR: Exception on /search [GET] [in C:\Users\a_smi\PycharmProjects\microblog\venv\lib\site-packages\flask\app.py:1891]
Traceback (most recent call last):
  File "C:\Users\a_smi\PycharmProjects\microblog\venv\lib\site-packages\flask\app.py", line 2446, in wsgi_app
    response = self.full_dispatch_request()
  File "C:\Users\a_smi\PycharmProjects\microblog\venv\lib\site-packages\flask\app.py", line 1951, in full_dispatch_request
    rv = self.handle_user_exception(e)
  File "C:\Users\a_smi\PycharmProjects\microblog\venv\lib\site-packages\flask\app.py", line 1820, in handle_user_exception
    reraise(exc_type, exc_value, tb)
  File "C:\Users\a_smi\PycharmProjects\microblog\venv\lib\site-packages\flask\_compat.py", line 39, in reraise
    raise value
  File "C:\Users\a_smi\PycharmProjects\microblog\venv\lib\site-packages\flask\app.py", line 1949, in full_dispatch_request
    rv = self.dispatch_request()
  File "C:\Users\a_smi\PycharmProjects\microblog\venv\lib\site-packages\flask\app.py", line 1935, in dispatch_request
    return self.view_functions[rule.endpoint](**req.view_args)
  File "C:\Users\a_smi\PycharmProjects\microblog\venv\lib\site-packages\flask_login\utils.py", line 261, in decorated_view
    return func(*args, **kwargs)
  File "C:\Users\a_smi\PycharmProjects\microblog\app\main\routes.py", line 143, in search
    current_app.config['POSTS_PER_PAGE'])
  File "C:\Users\a_smi\PycharmProjects\microblog\app\models.py", line 82, in search
    ids, total = query_index(cls.__tablename__, expression, page, per_page)
  File "C:\Users\a_smi\PycharmProjects\microblog\app\search.py", line 25, in query_index
    'from': (page - 1) * per_page, 'size': per_page})
  File "C:\Users\a_smi\PycharmProjects\microblog\venv\lib\site-packages\elasticsearch\client\utils.py", line 84, in _wrapped
    return func(*args, params=params, **kwargs)
  File "C:\Users\a_smi\PycharmProjects\microblog\venv\lib\site-packages\elasticsearch\client\__init__.py", line 1548, in search
    "GET", _make_path(index, doc_type, "_search"), params=params, body=body
  File "C:\Users\a_smi\PycharmProjects\microblog\venv\lib\site-packages\elasticsearch\transport.py", line 358, in perform_request
    timeout=timeout,
  File "C:\Users\a_smi\PycharmProjects\microblog\venv\lib\site-packages\elasticsearch\connection\http_urllib3.py", line 261, in perform_request
    self._raise_error(response.status, raw_data)
  File "C:\Users\a_smi\PycharmProjects\microblog\venv\lib\site-packages\elasticsearch\connection\base.py", line 182, in _raise_error
    status_code, error_message, additional_info
elasticsearch.exceptions.NotFoundError: NotFoundError(404, 'index_not_found_exception', 'no such index [post]', post, index_or_alias)
2020-02-07 19:27:06,662 INFO: Microblog startup [in C:\Users\a_smi\PycharmProjects\microblog\app\__init__.py:77]
2020-02-07 19:33:43,447 INFO: Microblog startup [in C:\Users\a_smi\PycharmProjects\microblog\app\__init__.py:77]
